<?xml version="1.0"?>
<robot xmlns:xacro="http://www.ros.org/wiki/xacro" >
<xacro:macro name="model_wrist" params="parent">

<!--<link name="cyberhand_forearm">
    <visual>
      <origin xyz="0 0 0" rpy="0 0 0" />
      <geometry name="cyberhand_forearm_geom">
         <mesh filename="file://$(find hand)/mesh/hand/forearm.stl"/>
      </geometry>
      <material name="Cream" />
    </visual>
  </link>

  <link name="virtual">
  </link>-->

  <link name="palm">
    <visual>
      <origin xyz="0 0 0" rpy="0 0 0" />
      <geometry name="cyberhand_forearm_geom">
         <mesh filename="file://$(find hand)/mesh/hand/palm.stl"/>
      </geometry>
      <material name="Cream" />
    </visual>
  </link>
 <!--joints-->
 <!--<joint name="attachment" type="fixed">
   <parent link="${parent}"/>
   <child link="cyberhand_forearm"/>
   <origin xyz="0.137837 0.0160406 -0.00177853" rpy="1.57 0  1.57" />
 </joint>


 <joint name="G_WristPitch" type="revolute">
    <parent link="cyberhand_forearm"/>
    <child link="virtual"/>  
    <origin xyz="0 0 0" rpy="0 0 0" />
    <axis xyz="1 0 0" />
    <limit lower="0" upper="2" effort="10" velocity="1.0"/>
  </joint>-->

 <joint name="G_W" type="revolute">
    <parent link="${parent}"/>
    <child link="palm"/>  
    <origin xyz="0 0 0" rpy="0 0 0" />
    <axis xyz="0 1 0" />
    <limit lower="0" upper="2" effort="10" velocity="1.0"/>
  </joint>

</xacro:macro>
</robot>



